### version information

```
pre-commit version: 4.3.0
git --version: git version 2.34.1
sys.version:
    3.10.12 (main, Aug 15 2025, 14:32:43) [GCC 11.4.0]
sys.executable: /home/vinniny/.local/pipx/venvs/pre-commit/bin/python
os.name: posix
sys.platform: linux
```

### error information

```
An error has occurred: FatalError: git failed. Is it installed, and are you in a Git repository directory?
```

```
Traceback (most recent call last):
  File "/home/vinniny/.local/pipx/venvs/pre-commit/lib/python3.10/site-packages/pre_commit/git.py", line 58, in get_root
    cmd_output('git', 'rev-parse', '--show-cdup')[1].strip(),
  File "/home/vinniny/.local/pipx/venvs/pre-commit/lib/python3.10/site-packages/pre_commit/util.py", line 117, in cmd_output
    returncode, stdout_b, stderr_b = cmd_output_b(*cmd, **kwargs)
  File "/home/vinniny/.local/pipx/venvs/pre-commit/lib/python3.10/site-packages/pre_commit/util.py", line 111, in cmd_output_b
    raise CalledProcessError(returncode, cmd, stdout_b, stderr_b)
pre_commit.util.CalledProcessError: command: ('/usr/bin/git', 'rev-parse', '--show-cdup')
return code: 128
stdout: (none)
stderr:
    fatal: not a git repository (or any of the parent directories): .git

During handling of the above exception, another exception occurred:

Traceback (most recent call last):
  File "/home/vinniny/.local/pipx/venvs/pre-commit/lib/python3.10/site-packages/pre_commit/error_handler.py", line 73, in error_handler
    yield
  File "/home/vinniny/.local/pipx/venvs/pre-commit/lib/python3.10/site-packages/pre_commit/main.py", line 373, in main
    _adjust_args_and_chdir(args)
  File "/home/vinniny/.local/pipx/venvs/pre-commit/lib/python3.10/site-packages/pre_commit/main.py", line 183, in _adjust_args_and_chdir
    toplevel = git.get_root()
  File "/home/vinniny/.local/pipx/venvs/pre-commit/lib/python3.10/site-packages/pre_commit/git.py", line 64, in get_root
    raise FatalError(
pre_commit.errors.FatalError: git failed. Is it installed, and are you in a Git repository directory?
```
